Workbook

Sheet Master Kas
A1: Tanggal | B1: Sumber Dana | C1: Keterangan | D1: Masuk | E1: Keluar | F1: Saldo
A2: 46122 | B2: Kas Rayhan | C2: Saldo Awal | D2: 2500000 | E2: 0 | F2: =D2-E2 -> 2500000
A3: 46122 | B3: Kas Azka | C3: Saldo Awal | D3: 2500000 | E3: 0 | F3: =D3-E3 -> 2500000
A4: 46123 | B4: Kas Rayhan | C4: Split Instalasi WIFI | D4: 0 | E4: 50000 | F4: =F3-E4 -> 2450000
A5: 46123 | B5: Kas Azka | C5: Split Instalasi WIFI | D5: 0 | E5: 50000 | F5: =F2-E5 -> 2450000
A6: 46132 | B6: Kas Rayhan | C6: Bayar Laundry | D6: 0 | E6: 69200 | F6: =F4-E6 -> 2380800
A7: 46133 | B7: Kas Rayhan | C7: Split Beli Lampu Depan | D7: 0 | E7: 9000 | F7: =F6-E7 -> 2371800
A8: 46133 | B8: Kas Azka | C8: Split Beli Lampu Depan | D8: 0 | E8: 9000 | F8: =F5-E8 -> 2441000
A9: 46133 | B9: Kas Rayhan | C9: Split Beli Lampu Tengah | D9: 0 | E9: =67800/2 -> 33900 | F9: =F7-E9 -> 2337900
A10: 46133 | B10: Kas Azka | C10: Split Beli Lampu Tengah | D10: 0 | E10: 33900 | F10: =F8-E10 -> 2407100
A11: 46134 | B11: Kas Azka | C11: Pemeliharaan Rumput | D11: 0 | E11: 250000 | F11: =F10-E11 -> 2157100
A12: 46134 | B12: Kas Rayhan | C12: Pemeliharaan Rumput | D12: 0 | E12: 250000 | F12: =F9-E12 -> 2087900
A13: 46135 | B13: Kas Azka | C13: Listrik April | D13: 0 | E13: 200000 | F13: =F11-E13 -> 1957100
A14: 46134 | B14: Kas Rayhan | C14: Obat Rumput | D14: 0 | E14: 25000 | F14: =F12-E14 -> 2062900
A15: 46134 | B15: Kas Azka | C15: Obat Rumput | D15: 0 | E15: 25000 | F15: =F13-E15 -> 1932100
A16: 46143 | B16: Kas Azka | C16: Sewa Rumdin | D16: 0 | E16: 200000 | F16: =F15-E16 -> 1732100
A17: 46143 | B17: Kas Azka | C17: Listrik Mei | D17: 0 | E17: 500000 | F17: =F16-E17 -> 1232100
A18: 46143 | B18: Kas Rayhan | C18: Sewa Rumdin | D18: 0 | E18: 185000 | F18: =F14-E18 -> 1877900
A19: 46143 | B19: Kas Azka | C19: Tagihan PDAM | D19: 0 | E19: 31000 | F19: =F17-E19 -> 1201100
A20: 46162 | B20: Kas Azka | C20: Tagihan Indihome | D20: 0 | E20: 99345 | F20: =F19-E20 -> 1101755
A21: 46162 | B21: Kas Rayhan | C21: Tagihan Indihome | D21: 0 | E21: 99345 | F21: =F18-E21 -> 1778555
A22: 46174 | B22: Kas Azka | C22: Listrik Juni | D22: 0 | E22: 250000 | F22: =F20-E22 -> 851755
A23: 46174 | B23: Kas Rayhan | C23: Listrik Juni | D23: 0 | E23: 250000 | F23: =F21-E23 -> 1528555
A24: 46174 | B24: Kas Azka | C24: Sewa Rumdin | D24: 0 | E24: 245000 | F24: =F22-E24 -> 606755
A25: 46174 | B25: Kas Rayhan | C25: Sewa Rumdin | D25: 0 | E25: 200000 | F25: =F23-E25 -> 1328555
A26: 46174 | B26: Kas Rayhan | C26: Tagihan Indihome | D26: 0 | E26: 155000 | F26: =F25-E26 -> 1173555
A27: 46174 | B27: Kas Azka | C27: Tagihan Indihome | D27: 0 | E27: 155000 | F27: =F24-E27 -> 451755
A28: 46174 | B28: Kas Rayhan | C28: Tagihan PDAM | D28: 0 | E28: 46500 | F28: =F26-E28 -> 1127055
A29: 46174 | B29: Kas Azka | C29: Tagihan PDAM | D29: 0 | E29: =46500 -> 46500 | F29: =F27-E29 -> 405255
A30: 46201 | B30: Kas Rayhan | C30: Split Kulkas | D30: 0 | E30: 250000 | F30: =F28-E30 -> 877055
A31: 46201 | B31: Kas Azka | C31: Split Kulkas | D31: 0 | E31: 250000 | F31: =F29-E31 -> 155255
A32: 46201 | B32: Kas Azka | C32: Split Ongkir Kulkas | D32: 0 | E32: 50000 | F32: =F31-E32 -> 105255
A33: 46201 | B33: Kas Azka | C33: Double Tip | D33: 0 | E33: 5000 | F33: =F32-E33 -> 100255
A34: 46201 | B34: Kas Azka | C34: Split Kran Dapur | D34: 0 | E34: 22500 | F34: =F33-E34 -> 77755
A35: 46201 | B35: Kas Rayhan | C35: Splti Kran Dapur | D35: 0 | E35: 22500 | F35: =F30-E35 -> 854555
A36: 46201 | B36: Kas Rayhan | C36: Cat Kamar | D36: 0 | E36: 168000 | F36: =F35-E36 -> 686555
A37: 46201 | B37: Kas Rayhan | C37: Kunci Jendela, Kelengkapan Cat (Roller, amplas, dll) | D37: 0 | E37: 85280 | F37: =F36-E37 -> 601275
A38: 46204 | B38: Kas Azka | C38: Inject Dana | D38: 1000000 | E38: 0 | F38: =F34+D38 -> 1077755
A39: 46204 | B39: Kas Azka | C39: Sewa Rumdin | D39: 0 | E39: 245000 | F39: =F38-E39 -> 832755
A40: 46204 | B40: Kas Rayhan | C40: Sewa Rumdin | D40: 0 | E40: 200000 | F40: =F37-E40 -> 401275
...

Sheet Sisa Kas
A1: Sumber Dana | B1: Total Masuk | C1: Total Keluar | D1: Saldo Akhir
A2: Kas Rayhan | B2: =SUMIF('Master Kas'!B:B,"Kas Rayhan",'Master Kas'!D:D) -> 3500000 | C2: =SUMIF('Master Kas'!B:B,"Kas Rayhan",'Master Kas'!E:E) -> 2639225 | D2: =B2-C2 -> 860775
A3: Kas Azka | B3: =SUMIF('Master Kas'!B:B,"Kas Azka",'Master Kas'!D:D) -> 3500000 | C3: =SUMIF('Master Kas'!B:B,"Kas Azka",'Master Kas'!E:E) -> 3205995 | D3: =B3-C3 -> 294005

Sheet Dashboard
A1: Dashboard Kas
A3: Saldo Kas Rayhan | B3: ='Sisa Kas'!D2 -> 860775
A4: Kebutuhan per Bulan (Rayhan) | B4: 715000
A5: Estimasi Bertahan (Bulan) | B5: =IFERROR(B3/B4,0) -> 1.2038811

Sheet Biaya Bulanan
A1: Rayhan
A2: Komponen | B2: Total
A3: Sewa | B3: 200000
A4: Indihome | B4: 155000
A5: Listrik | B5: 300000
A6: Air | B6: 50000
A7: Total | B7: =SUM(B3:B6) -> 705000
A9: Azka
A10: Komponen | B10: Total
A11: Sewa | B11: 245000
A12: Indihome | B12: 155000
A13: Listrik | B13: 300000
A14: Air | B14: 50000
A15: Total | B15: =SUM(B11:B14) -> 750000
